Workbook

Sheet Start Here
B2: TALENT POOL SYSTEM · FREE DEMO
B3: Candidate Talent Pool
B4: Recruit • Learn • Store • Reuse
B5: Turn every candidate you meet into an asset for your next vacancy.
B8: Licensed software. Single-company use, up to 5 users. No resale or redistribution. Full license at the bottom of this page ↓
B9: CREATED BY | I9: WANT FULL ACCESS?
B10: =Settings!B2 -> Mohammad Zargar | I10: This is a view-only demo. Message me and I will give you full access, so you can add candidates, log follow-ups and test it with your own data.
B11: =Settings!B3 -> Process Improvement & Business Systems
B12: =HYPERLINK(IF(LEFT(Settings!B4,4)="http",Settings!B4,"https://"&Settings!B4),"💼 LinkedIn: "&SUBSTITUTE(SUBSTITUTE(Settings!B4,"https://",""),"www.","")) -> 💼 LinkedIn: linkedin.com/mohammad-zargar
B13: =HYPERLINK("mailto:"&Settings!B5,"✉️ Email: "&Settings!B5) -> ✉️ Email: s.mohammad.zargar@gmail.com | J13: =HYPERLINK("mailto:"&Settings!B5&"?subject="&SUBSTITUTE(Settings!B6," ","%20"),"Request full access →") -> Request full access →
B16: WHAT IT DOES
B17: 🗂️ | F17: 🔎 | J17: 🔔
B18: Remember everyone | F18: Find matches in seconds | J18: Never miss a follow-up
B19: Every candidate you meet is saved with skills, status and consent, hired or not. | F19: Pick a vacancy and get a ranked list of people you already know, scored out of 100. | J19: See who to contact today or tomorrow and log every conversation in one place.
B21: GET STARTED IN 3 STEPS
B22: 1 | F22: 2 | J22: 3
B23: Add | F23: Find | J23: Follow up
B24: After each hiring round, register every candidate in the Add Candidate tab. | F24: When a position opens, pick it in Find Candidates and see the best matches. | J24: Log every contact in Follow-Up and watch the Dashboard.
B26: TABS AT A GLANCE
B27: 📊 Dashboard | E27: Candidates recorded, hired, open positions, who to contact today or tomorrow, plus charts.
B28: ➕ Add Candidate | E28: The form you use to register a candidate.
B29: 🗂️ Candidates | E29: The database. One row per candidate, with colors for status and future potential.
B30: 🔔 Follow-Up 🔒 | E30: 🔒 Premium. Log every contact with a candidate, and see who is due to be contacted next.
B31: 🔎 Find Candidates 🔒 | E31: 🔒 Premium. Pick a vacancy and get a ranked list of past candidates who may fit.
B32: 📌 Positions | E32: Your job positions: status (Open, On Hold, Closed), openings, hiring manager, requirements.
B33: 📝 Contact Log 🔒 | E33: 🔒 Premium. The history of every follow-up. Filled automatically.
B34: 📋 Lists | E34: The values behind the dropdown menus (skills, statuses, cities).
B36: Full instructions
B37: Everything you need to use the workbook, step by step.
B38: A. ADD A CANDIDATE (about 1 minute)
B39: Step 1 | E39: Open the Add Candidate tab.
B40: Step 2 | E40: Fill in the yellow cells from top to bottom. Use the dropdown arrows wherever you see one. Required fields are marked in the hint column.
B41: Step 3 | E41: Click the ADD CANDIDATE button (or the menu Talent Pool > Add candidate).
B42: Step 4 | E42: The form clears and the candidate appears at the bottom of the Candidates tab with an ID like CAN-2026-00041.
B43: Good to know | E43: Recruitment status is what happened in this hiring round. Future potential is whether you would consider this person for a different role later. Someone who was Not Selected can still be a Strong Future Fit.
B44: Consent | E44: Choose Yes only if the candidate agreed to be kept in your talent pool. Candidates without consent never appear in match results.
B46: B. MANAGE JOB POSITIONS
B47: Step 1 | E47: Open the Positions tab. Each row is one job position with its department, location, salary budget, required skills, status, number of openings, date opened, hiring manager and priority.
B48: Step 2 | E48: To add a position, fill in the next empty row (up to row 51). Use the dropdowns for Status and Priority.
B49: Status | E49: Open = you are hiring now. On Hold = paused. Closed = filled or cancelled. Only Open positions are counted on the Dashboard.
...

Sheet Dashboard
A1: Dashboard
A2: Your talent pool at a glance. Recruit, learn, store, reuse.
A4: 👥 CANDIDATES RECORDED | D4: ✅ ACCEPTED (HIRED) | G4: 📌 OPEN POSITIONS | J4: ⏰ DUE TODAY OR TOMORROW
A5: =COUNTA(Candidates!$A$2:$A$201) -> 40 | D5: =COUNTIF(Candidates!$M$2:$M$201,"Hired") -> 5 | G5: =COUNTIF(Positions!$L$2:$L$51,"Open") -> 6 | J5: =COUNTIF(Candidates!$X$2:$X$201,1)+COUNTIF(Candidates!$X$2:$X$201,2) -> 5
A7: in the talent pool | D7: ="Hired = "&IF(COUNTA(Candidates!$A$2:$A$201)=0,"0%",TEXT(COUNTIF(Candidates!$M$2:$M$201,"Hired")/COUNTA(Candidates!$A$2:$A$201),"0%"))&" of all candidates" -> Hired = 13% of all candidates | G7: =SUMIF(Positions!$L$2:$L$51,"Open",Positions!$M$2:$M$51)&" openings to fill" -> 10 openings to fill | J7: ="Today: "&COUNTIF(Candidates!$X$2:$X$201,1)&" | Tomorrow: "&COUNTIF(Candidates!$X$2:$X$201,2) -> Today: 2 | Tomorrow: 3
A9: 📌 OPEN POSITIONS | G9: ⏰ FOLLOW-UP DUE TODAY OR TOMORROW
A10: Position | Department | D10: Location | E10: Openings | F10: Days open | G10: Candidate | I10: Applied for | K10: Due | L10: Future fit
A11: =IFERROR(INDEX(Positions!$C$2:$C$51,MATCH(1,Positions!$Q$2:$Q$51,0))&" | "&INDEX(Positions!$B$2:$B$51,MATCH(1,Positions!$Q$2:$Q$51,0)),IF(1=1,"No open positions","")) -> Operations Manager | Operations | D11: =IFERROR(INDEX(Positions!$E$2:$E$51,MATCH(1,Positions!$Q$2:$Q$51,0)),"") -> Chicago, IL | E11: =IFERROR(INDEX(Positions!$M$2:$M$51,MATCH(1,Positions!$Q$2:$Q$51,0)),"") -> 1 | F11: =IFERROR(TODAY()-INDEX(Positions!$N$2:$N$51,MATCH(1,Positions!$Q$2:$Q$51,0)),"") -> 27 | G11: =IFERROR(INDEX(Candidates!$C$2:$C$201,MATCH(1,Candidates!$Y$2:$Y$201,0)),IF(1=1,"Nobody is due today or tomorrow","")) -> Jessica Miller | I11: =IFERROR(INDEX(Candidates!$E$2:$E$201,MATCH(1,Candidates!$Y$2:$Y$201,0)),"") -> Quality Engineer | K11: =IFERROR(IF(INDEX(Candidates!$X$2:$X$201,MATCH(1,Candidates!$Y$2:$Y$201,0))=1,"Today","Tomorrow"),"") -> Today | L11: =IFERROR(IF(INDEX(Candidates!$N$2:$N$201,MATCH(1,Candidates!$Y$2:$Y$201,0))="Strong Future Fit","Strong","Potential"),"") -> Potential
A12: =IFERROR(INDEX(Positions!$C$2:$C$51,MATCH(2,Positions!$Q$2:$Q$51,0))&" | "&INDEX(Positions!$B$2:$B$51,MATCH(2,Positions!$Q$2:$Q$51,0)),IF(2=1,"No open positions","")) -> Data Analyst | Analytics | D12: =IFERROR(INDEX(Positions!$E$2:$E$51,MATCH(2,Positions!$Q$2:$Q$51,0)),"") -> Austin, TX | E12: =IFERROR(INDEX(Positions!$M$2:$M$51,MATCH(2,Positions!$Q$2:$Q$51,0)),"") -> 2 | F12: =IFERROR(TODAY()-INDEX(Positions!$N$2:$N$51,MATCH(2,Positions!$Q$2:$Q$51,0)),"") -> 20 | G12: =IFERROR(INDEX(Candidates!$C$2:$C$201,MATCH(2,Candidates!$Y$2:$Y$201,0)),IF(2=1,"Nobody is due today or tomorrow","")) -> Jessica Thomas | I12: =IFERROR(INDEX(Candidates!$E$2:$E$201,MATCH(2,Candidates!$Y$2:$Y$201,0)),"") -> Marketing Manager | K12: =IFERROR(IF(INDEX(Candidates!$X$2:$X$201,MATCH(2,Candidates!$Y$2:$Y$201,0))=1,"Today","Tomorrow"),"") -> Today | L12: =IFERROR(IF(INDEX(Candidates!$N$2:$N$201,MATCH(2,Candidates!$Y$2:$Y$201,0))="Strong Future Fit","Strong","Potential"),"") -> Potential
A13: =IFERROR(INDEX(Positions!$C$2:$C$51,MATCH(3,Positions!$Q$2:$Q$51,0))&" | "&INDEX(Positions!$B$2:$B$51,MATCH(3,Positions!$Q$2:$Q$51,0)),IF(3=1,"No open positions","")) -> HR Generalist | Human Resources | D13: =IFERROR(INDEX(Positions!$E$2:$E$51,MATCH(3,Positions!$Q$2:$Q$51,0)),"") -> Atlanta, GA | E13: =IFERROR(INDEX(Positions!$M$2:$M$51,MATCH(3,Positions!$Q$2:$Q$51,0)),"") -> 1 | F13: =IFERROR(TODAY()-INDEX(Positions!$N$2:$N$51,MATCH(3,Positions!$Q$2:$Q$51,0)),"") -> 13 | G13: =IFERROR(INDEX(Candidates!$C$2:$C$201,MATCH(3,Candidates!$Y$2:$Y$201,0)),IF(3=1,"Nobody is due today or tomorrow","")) -> Jessica Anderson | I13: =IFERROR(INDEX(Candidates!$E$2:$E$201,MATCH(3,Candidates!$Y$2:$Y$201,0)),"") -> Quality Engineer | K13: =IFERROR(IF(INDEX(Candidates!$X$2:$X$201,MATCH(3,Candidates!$Y$2:$Y$201,0))=1,"Today","Tomorrow"),"") -> Tomorrow | L13: =IFERROR(IF(INDEX(Candidates!$N$2:$N$201,MATCH(3,Candidates!$Y$2:$Y$201,0))="Strong Future Fit","Strong","Potential"),"") -> Potential
A14: =IFERROR(INDEX(Positions!$C$2:$C$51,MATCH(4,Positions!$Q$2:$Q$51,0))&" | "&INDEX(Positions!$B$2:$B$51,MATCH(4,Positions!$Q$2:$Q$51,0)),IF(4=1,"No open positions","")) -> Account Executive | Sales | D14: =IFERROR(INDEX(Positions!$E$2:$E$51,MATCH(4,Positions!$Q$2:$Q$51,0)),"") -> Dallas, TX | E14: =IFERROR(INDEX(Positions!$M$2:$M$51,MATCH(4,Positions!$Q$2:$Q$51,0)),"") -> 3 | F14: =IFERROR(TODAY()-INDEX(Positions!$N$2:$N$51,MATCH(4,Positions!$Q$2:$Q$51,0)),"") -> 34 | G14: =IFERROR(INDEX(Candidates!$C$2:$C$201,MATCH(4,Candidates!$Y$2:$Y$201,0)),IF(4=1,"Nobody is due today or tomorrow","")) -> Megan Martin | I14: =IFERROR(INDEX(Candidates!$E$2:$E$201,MATCH(4,Candidates!$Y$2:$Y$201,0)),"") -> Quality Engineer | K14: =IFERROR(IF(INDEX(Candidates!$X$2:$X$201,MATCH(4,Candidates!$Y$2:$Y$201,0))=1,"Today","Tomorrow"),"") -> Tomorrow | L14: =IFERROR(IF(INDEX(Candidates!$N$2:$N$201,MATCH(4,Candidates!$Y$2:$Y$201,0))="Strong Future Fit","Strong","Potential"),"") -> Potential
A15: =IFERROR(INDEX(Positions!$C$2:$C$51,MATCH(5,Positions!$Q$2:$Q$51,0))&" | "&INDEX(Positions!$B$2:$B$51,MATCH(5,Positions!$Q$2:$Q$51,0)),IF(5=1,"No open positions","")) -> Marketing Manager | Marketing | D15: =IFERROR(INDEX(Positions!$E$2:$E$51,MATCH(5,Positions!$Q$2:$Q$51,0)),"") -> Denver, CO | E15: =IFERROR(INDEX(Positions!$M$2:$M$51,MATCH(5,Positions!$Q$2:$Q$51,0)),"") -> 1 | F15: =IFERROR(TODAY()-INDEX(Positions!$N$2:$N$51,MATCH(5,Positions!$Q$2:$Q$51,0)),"") -> 6 | G15: =IFERROR(INDEX(Candidates!$C$2:$C$201,MATCH(5,Candidates!$Y$2:$Y$201,0)),IF(5=1,"Nobody is due today or tomorrow","")) -> Jason White | I15: =IFERROR(INDEX(Candidates!$E$2:$E$201,MATCH(5,Candidates!$Y$2:$Y$201,0)),"") -> Staff Accountant | K15: =IFERROR(IF(INDEX(Candidates!$X$2:$X$201,MATCH(5,Candidates!$Y$2:$Y$201,0))=1,"Today","Tomorrow"),"") -> Tomorrow | L15: =IFERROR(IF(INDEX(Candidates!$N$2:$N$201,MATCH(5,Candidates!$Y$2:$Y$201,0))="Strong Future Fit","Strong","Potential"),"") -> Potential
A16: =IFERROR(INDEX(Positions!$C$2:$C$51,MATCH(6,Positions!$Q$2:$Q$51,0))&" | "&INDEX(Positions!$B$2:$B$51,MATCH(6,Positions!$Q$2:$Q$51,0)),IF(6=1,"No open positions","")) -> Software Engineer | Engineering | D16: =IFERROR(INDEX(Positions!$E$2:$E$51,MATCH(6,Positions!$Q$2:$Q$51,0)),"") -> Austin, TX | E16: =IFERROR(INDEX(Positions!$M$2:$M$51,MATCH(6,Positions!$Q$2:$Q$51,0)),"") -> 2 | F16: =IFERROR(TODAY()-INDEX(Positions!$N$2:$N$51,MATCH(6,Positions!$Q$2:$Q$51,0)),"") -> 18 | G16: =IFERROR(INDEX(Candidates!$C$2:$C$201,MATCH(6,Candidates!$Y$2:$Y$201,0)),IF(6=1,"Nobody is due today or tomorrow","")) | I16: =IFERROR(INDEX(Candidates!$E$2:$E$201,MATCH(6,Candidates!$Y$2:$Y$201,0)),"") | K16: =IFERROR(IF(INDEX(Candidates!$X$2:$X$201,MATCH(6,Candidates!$Y$2:$Y$201,0))=1,"Today","Tomorrow"),"") | L16: =IFERROR(IF(INDEX(Candidates!$N$2:$N$201,MATCH(6,Candidates!$Y$2:$Y$201,0))="Strong Future Fit","Strong","Potential"),"")
A17: =IFERROR(INDEX(Positions!$C$2:$C$51,MATCH(7,Positions!$Q$2:$Q$51,0))&" | "&INDEX(Positions!$B$2:$B$51,MATCH(7,Positions!$Q$2:$Q$51,0)),IF(7=1,"No open positions","")) | D17: =IFERROR(INDEX(Positions!$E$2:$E$51,MATCH(7,Positions!$Q$2:$Q$51,0)),"") | E17: =IFERROR(INDEX(Positions!$M$2:$M$51,MATCH(7,Positions!$Q$2:$Q$51,0)),"") | F17: =IFERROR(TODAY()-INDEX(Positions!$N$2:$N$51,MATCH(7,Positions!$Q$2:$Q$51,0)),"") | G17: =IFERROR(INDEX(Candidates!$C$2:$C$201,MATCH(7,Candidates!$Y$2:$Y$201,0)),IF(7=1,"Nobody is due today or tomorrow","")) | I17: =IFERROR(INDEX(Candidates!$E$2:$E$201,MATCH(7,Candidates!$Y$2:$Y$201,0)),"") | K17: =IFERROR(IF(INDEX(Candidates!$X$2:$X$201,MATCH(7,Candidates!$Y$2:$Y$201,0))=1,"Today","Tomorrow"),"") | L17: =IFERROR(IF(INDEX(Candidates!$N$2:$N$201,MATCH(7,Candidates!$Y$2:$Y$201,0))="Strong Future Fit","Strong","Potential"),"")
A18: =IFERROR(INDEX(Positions!$C$2:$C$51,MATCH(8,Positions!$Q$2:$Q$51,0))&" | "&INDEX(Positions!$B$2:$B$51,MATCH(8,Positions!$Q$2:$Q$51,0)),IF(8=1,"No open positions","")) | D18: =IFERROR(INDEX(Positions!$E$2:$E$51,MATCH(8,Positions!$Q$2:$Q$51,0)),"") | E18: =IFERROR(INDEX(Positions!$M$2:$M$51,MATCH(8,Positions!$Q$2:$Q$51,0)),"") | F18: =IFERROR(TODAY()-INDEX(Positions!$N$2:$N$51,MATCH(8,Positions!$Q$2:$Q$51,0)),"") | G18: =IFERROR(INDEX(Candidates!$C$2:$C$201,MATCH(8,Candidates!$Y$2:$Y$201,0)),IF(8=1,"Nobody is due today or tomorrow","")) | I18: =IFERROR(INDEX(Candidates!$E$2:$E$201,MATCH(8,Candidates!$Y$2:$Y$201,0)),"") | K18: =IFERROR(IF(INDEX(Candidates!$X$2:$X$201,MATCH(8,Candidates!$Y$2:$Y$201,0))=1,"Today","Tomorrow"),"") | L18: =IFERROR(IF(INDEX(Candidates!$N$2:$N$201,MATCH(8,Candidates!$Y$2:$Y$201,0))="Strong Future Fit","Strong","Potential"),"")
A19: =IF(COUNTIF(Positions!$L$2:$L$51,"Open")>8,"+ "&(COUNTIF(Positions!$L$2:$L$51,"Open")-8)&" more in the Positions tab","") | G19: =IF(COUNTIF(Candidates!$X$2:$X$201,1)+COUNTIF(Candidates!$X$2:$X$201,2)>8,"+ more in the Follow-Up tab","")
A56: Data behind the charts (automatic, do not edit)
A57: Status | B57: Count | D57: Future potential | E57: Count | G57: Department | H57: Count | J57: Follow-ups | K57: Count
A58: Applied | B58: =COUNTIF(Candidates!$M$2:$M$201,"Applied") -> 0 | D58: Strong Future Fit | E58: =COUNTIF(Candidates!$N$2:$N$201,"Strong Future Fit") -> 8 | G58: Operations | H58: =COUNTIF(Candidates!$F$2:$F$201,"Operations") -> 6 | J58: Overdue | K58: =COUNTIFS(Candidates!$R$2:$R$201,"<"&DATE(YEAR(TODAY()),MONTH(TODAY()),1),Candidates!$P$2:$P$201,"Yes") -> 1
A59: Screened | B59: =COUNTIF(Candidates!$M$2:$M$201,"Screened") -> 4 | D59: Potential Future Fit | E59: =COUNTIF(Candidates!$N$2:$N$201,"Potential Future Fit") -> 14 | G59: Analytics | H59: =COUNTIF(Candidates!$F$2:$F$201,"Analytics") -> 5 | J59: =TEXT(EDATE(DATE(YEAR(TODAY()),MONTH(TODAY()),1),0),"mmm yy") -> Oct 26 | K59: =COUNTIFS(Candidates!$R$2:$R$201,">="&EDATE(DATE(YEAR(TODAY()),MONTH(TODAY()),1),0),Candidates!$R$2:$R$201,"<"&EDATE(EDATE(DATE(YEAR(TODAY()),MONTH(TODAY()),1),0),1),Candidates!$P$2:$P$201,"Yes") -> 12
A60: Interviewed | B60: =COUNTIF(Candidates!$M$2:$M$201,"Interviewed") -> 4 | D60: Not Currently Relevant | E60: =COUNTIF(Candidates!$N$2:$N$201,"Not Currently Relevant") -> 16 | G60: Human Resources | H60: =COUNTIF(Candidates!$F$2:$F$201,"Human Resources") -> 4 | J60: =TEXT(EDATE(DATE(YEAR(TODAY()),MONTH(TODAY()),1),1),"mmm yy") -> Nov 26 | K60: =COUNTIFS(Candidates!$R$2:$R$201,">="&EDATE(DATE(YEAR(TODAY()),MONTH(TODAY()),1),1),Candidates!$R$2:$R$201,"<"&EDATE(EDATE(DATE(YEAR(TODAY()),MONTH(TODAY()),1),1),1),Candidates!$P$2:$P$201,"Yes") -> 0
A61: Offered | B61: =COUNTIF(Candidates!$M$2:$M$201,"Offered") -> 0 | D61: Do Not Contact | E61: =COUNTIF(Candidates!$N$2:$N$201,"Do Not Contact") -> 2 | G61: Finance | H61: =COUNTIF(Candidates!$F$2:$F$201,"Finance") -> 7 | J61: =TEXT(EDATE(DATE(YEAR(TODAY()),MONTH(TODAY()),1),2),"mmm yy") -> Dec 26 | K61: =COUNTIFS(Candidates!$R$2:$R$201,">="&EDATE(DATE(YEAR(TODAY()),MONTH(TODAY()),1),2),Candidates!$R$2:$R$201,"<"&EDATE(EDATE(DATE(YEAR(TODAY()),MONTH(TODAY()),1),2),1),Candidates!$P$2:$P$201,"Yes") -> 8
A62: Hired | B62: =COUNTIF(Candidates!$M$2:$M$201,"Hired") -> 5 | G62: Sales | H62: =COUNTIF(Candidates!$F$2:$F$201,"Sales") -> 3 | J62: =TEXT(EDATE(DATE(YEAR(TODAY()),MONTH(TODAY()),1),3),"mmm yy") -> Jan 27 | K62: =COUNTIFS(Candidates!$R$2:$R$201,">="&EDATE(DATE(YEAR(TODAY()),MONTH(TODAY()),1),3),Candidates!$R$2:$R$201,"<"&EDATE(EDATE(DATE(YEAR(TODAY()),MONTH(TODAY()),1),3),1),Candidates!$P$2:$P$201,"Yes") -> 0
A63: Not Selected | B63: =COUNTIF(Candidates!$M$2:$M$201,"Not Selected") -> 22 | G63: Marketing | H63: =COUNTIF(Candidates!$F$2:$F$201,"Marketing") -> 7 | J63: =TEXT(EDATE(DATE(YEAR(TODAY()),MONTH(TODAY()),1),4),"mmm yy") -> Feb 27 | K63: =COUNTIFS(Candidates!$R$2:$R$201,">="&EDATE(DATE(YEAR(TODAY()),MONTH(TODAY()),1),4),Candidates!$R$2:$R$201,"<"&EDATE(EDATE(DATE(YEAR(TODAY()),MONTH(TODAY()),1),4),1),Candidates!$P$2:$P$201,"Yes") -> 0
A64: Withdrawn | B64: =COUNTIF(Candidates!$M$2:$M$201,"Withdrawn") -> 5 | G64: Engineering | H64: =COUNTIF(Candidates!$F$2:$F$201,"Engineering") -> 8 | J64: =TEXT(EDATE(DATE(YEAR(TODAY()),MONTH(TODAY()),1),5),"mmm yy") -> Mar 27 | K64: =COUNTIFS(Candidates!$R$2:$R$201,">="&EDATE(DATE(YEAR(TODAY()),MONTH(TODAY()),1),5),Candidates!$R$2:$R$201,"<"&EDATE(EDATE(DATE(YEAR(TODAY()),MONTH(TODAY()),1),5),1),Candidates!$P$2:$P$201,"Yes") -> 0

Sheet Add Candidate
A1: Add a Candidate
A2: Step 1: fill the yellow cells. Step 2: click the ADD CANDIDATE button (or menu Talent Pool > Add candidate).
A4: 👤 1. About the candidate
A5: Name | C5: e.g. Jessica Taylor
A6: Contact | C6: e.g. jessica.taylor@email.com or (555) 123-4567
A7: Position applied for | C7: Pick from the list
A8: Department (automatic) | B8: =IFERROR(INDEX(Positions!$B$2:$B$51,MATCH(B7,Positions!$C$2:$C$51,0)),"") | C8: Filled in for you
A10: 🧩 2. Skills and fit
A11: Skill 1 | C11: Pick from the list. Required
A12: Skill 2 | C12: Optional
A13: Skill 3 | C13: Optional
A14: Skill 4 | C14: Optional
A15: Skill 5 | C15: Optional
A16: Years of experience | C16: Whole years, e.g. 4
A17: Expected salary (USD/year) | C17: Annual salary in USD, e.g. 85000
A18: Location | C18: Pick from the list
A19: Notice period (days) | C19: Days until they could start, e.g. 14
A21: 📋 3. Hiring outcome
A22: Source | C22: Where the candidate came from
A23: Recruitment status | C23: What happened in this hiring round
A24: Future potential | C24: Could this person fit a FUTURE role? (separate from status)
A25: Reason for decision | C25: Short note, e.g. Salary above budget
A27: 🔔 4. Future contact
A28: Interested in future roles? | C28: Yes / No
A29: Consent to keep their data? | C29: Must be Yes to be used in matching
A30: Next follow-up date | C30: When to contact them again
A32: Tip: all data in this file is fictional demo data.
A33: Yellow = you type or pick. Grey = automatic.

Sheet Candidates
A1: Candidate ID | B1: Date Added | C1: Name | D1: Contact | E1: Position Applied | F1: Department | G1: Skills | H1: Years of Experience | I1: Expected Salary (USD/year) | J1: Location | K1: Notice Period (days) | L1: Source | M1: Recruitment Status | N1: Future Potential | O1: Reason for Decision | P1: Interested in Future Roles | Q1: Consent to Retain Data | R1: Next Follow-up Date | S1: Last Contact Date | T1: Last Contact Outcome | U1: due (helper) | V1: due # (helper) | W1: label (helper) | X1: today/tomorrow (helper) | Y1: today/tomorrow # (helper)
A2: CAN-2026-00001 | B2: 46086 | C2: Jason Martinez | D2: jason.martinez@example.com | E2: Marketing Manager | F2: Marketing | G2: Google Analytics, SEO, Budgeting | H2: 2 | I2: 110000 | J2: Chicago, IL | K2: 14 | L2: LinkedIn | M2: Withdrawn | N2: Potential Future Fit | O2: Relocation not possible | P2: Yes | Q2: No | R2: 46361 | S2: 46293 | T2: Interested | U2: =IF(A2="","",IF(AND(R2<>"",R2<=TODAY()+30,P2="Yes",Q2="Yes",N2<>"Do Not Contact"),1,0)) -> 0 | V2: =IF(U2=1,COUNTIF($U$2:U2,1),"") | W2: =IF(A2="","",A2&" | "&C2) -> CAN-2026-00001 | Jason Martinez | X2: =IF(A2="","",IF(AND(R2<>"",P2="Yes",Q2="Yes",N2<>"Do Not Contact"),IF(INT(R2)=TODAY(),1,IF(INT(R2)=TODAY()+1,2,0)),0)) -> 0 | Y2: =IF(OR(X2=1,X2=2),COUNTIF($X$2:X2,1)+COUNTIF($X$2:X2,2),"")
A3: CAN-2026-00002 | B3: 46086 | C3: Daniel Jackson | D3: daniel.jackson@example.com | E3: Staff Accountant | F3: Finance | G3: Excel, QuickBooks, Reconciliation, Accounts Payable | H3: 9 | I3: 69000 | J3: Austin, TX | K3: 60 | L3: Indeed | M3: Not Selected | N3: Not Currently Relevant | O3: Insufficient experience for this level | P3: Yes | Q3: No | U3: =IF(A3="","",IF(AND(R3<>"",R3<=TODAY()+30,P3="Yes",Q3="Yes",N3<>"Do Not Contact"),1,0)) -> 0 | V3: =IF(U3=1,COUNTIF($U$2:U3,1),"") | W3: =IF(A3="","",A3&" | "&C3) -> CAN-2026-00002 | Daniel Jackson | X3: =IF(A3="","",IF(AND(R3<>"",P3="Yes",Q3="Yes",N3<>"Do Not Contact"),IF(INT(R3)=TODAY(),1,IF(INT(R3)=TODAY()+1,2,0)),0)) -> 0 | Y3: =IF(OR(X3=1,X3=2),COUNTIF($X$2:X3,1)+COUNTIF($X$2:X3,2),"")
A4: CAN-2026-00003 | B4: 46093 | C4: Amanda Anderson | D4: amanda.anderson@example.com | E4: Staff Accountant | F4: Finance | G4: Excel, Reconciliation, QuickBooks | H4: 10 | I4: 72000 | J4: Austin, TX | K4: 14 | L4: Staffing Agency | M4: Hired | N4: Not Currently Relevant | O4: Best overall fit | P4: Yes | Q4: Yes | U4: =IF(A4="","",IF(AND(R4<>"",R4<=TODAY()+30,P4="Yes",Q4="Yes",N4<>"Do Not Contact"),1,0)) -> 0 | V4: =IF(U4=1,COUNTIF($U$2:U4,1),"") | W4: =IF(A4="","",A4&" | "&C4) -> CAN-2026-00003 | Amanda Anderson | X4: =IF(A4="","",IF(AND(R4<>"",P4="Yes",Q4="Yes",N4<>"Do Not Contact"),IF(INT(R4)=TODAY(),1,IF(INT(R4)=TODAY()+1,2,0)),0)) -> 0 | Y4: =IF(OR(X4=1,X4=2),COUNTIF($X$2:X4,1)+COUNTIF($X$2:X4,2),"")
A5: CAN-2026-00004 | B5: 46099 | C5: Ashley Martinez | D5: ashley.martinez@example.com | E5: Quality Engineer | F5: Engineering | G5: ISO 9001, FMEA, Root Cause Analysis, Git, Process Improvement | H5: 2 | I5: 106000 | J5: Columbus, OH | K5: 14 | L5: LinkedIn | M5: Not Selected | N5: Strong Future Fit | O5: Skill gap in a key requirement | P5: Yes | Q5: Yes | R5: 46387 | S5: 46293 | T5: Interested | U5: =IF(A5="","",IF(AND(R5<>"",R5<=TODAY()+30,P5="Yes",Q5="Yes",N5<>"Do Not Contact"),1,0)) -> 0 | V5: =IF(U5=1,COUNTIF($U$2:U5,1),"") | W5: =IF(A5="","",A5&" | "&C5) -> CAN-2026-00004 | Ashley Martinez | X5: =IF(A5="","",IF(AND(R5<>"",P5="Yes",Q5="Yes",N5<>"Do Not Contact"),IF(INT(R5)=TODAY(),1,IF(INT(R5)=TODAY()+1,2,0)),0)) -> 0 | Y5: =IF(OR(X5=1,X5=2),COUNTIF($X$2:X5,1)+COUNTIF($X$2:X5,2),"")
A6: CAN-2026-00005 | B6: 46103 | C6: Joshua Martinez | D6: joshua.martinez@example.com | E6: Staff Accountant | F6: Finance | G6: QuickBooks, Excel, Accounts Payable, GAAP, Tableau | H6: 2 | I6: 79000 | J6: Denver, CO | K6: 14 | L6: Company Website | M6: Not Selected | N6: Potential Future Fit | O6: Salary expectation above budget | P6: Yes | Q6: Yes | R6: 46386 | S6: 46285 | T6: No response | U6: =IF(A6="","",IF(AND(R6<>"",R6<=TODAY()+30,P6="Yes",Q6="Yes",N6<>"Do Not Contact"),1,0)) -> 0 | V6: =IF(U6=1,COUNTIF($U$2:U6,1),"") | W6: =IF(A6="","",A6&" | "&C6) -> CAN-2026-00005 | Joshua Martinez | X6: =IF(A6="","",IF(AND(R6<>"",P6="Yes",Q6="Yes",N6<>"Do Not Contact"),IF(INT(R6)=TODAY(),1,IF(INT(R6)=TODAY()+1,2,0)),0)) -> 0 | Y6: =IF(OR(X6=1,X6=2),COUNTIF($X$2:X6,1)+COUNTIF($X$2:X6,2),"")
A7: CAN-2026-00006 | B7: 46107 | C7: Kevin Davis | D7: kevin.davis@example.com | E7: Operations Manager | F7: Operations | G7: Supply Chain, Team Leadership, Process Improvement, Budgeting | H7: 9 | I7: 103000 | J7: Chicago, IL | K7: 14 | L7: Company Website | M7: Not Selected | N7: Not Currently Relevant | O7: Skill gap in a key requirement | P7: Yes | Q7: No | U7: =IF(A7="","",IF(AND(R7<>"",R7<=TODAY()+30,P7="Yes",Q7="Yes",N7<>"Do Not Contact"),1,0)) -> 0 | V7: =IF(U7=1,COUNTIF($U$2:U7,1),"") | W7: =IF(A7="","",A7&" | "&C7) -> CAN-2026-00006 | Kevin Davis | X7: =IF(A7="","",IF(AND(R7<>"",P7="Yes",Q7="Yes",N7<>"Do Not Contact"),IF(INT(R7)=TODAY(),1,IF(INT(R7)=TODAY()+1,2,0)),0)) -> 0 | Y7: =IF(OR(X7=1,X7=2),COUNTIF($X$2:X7,1)+COUNTIF($X$2:X7,2),"")
A8: CAN-2026-00007 | B8: 46120 | C8: Nicole Brown | D8: nicole.brown@example.com | E8: Marketing Manager | F8: Marketing | G8: Google Analytics, SEO, Content Strategy, Email Marketing | H8: 5 | I8: 96000 | J8: Atlanta, GA | K8: 14 | L8: Referral | M8: Not Selected | N8: Strong Future Fit | O8: Insufficient experience for this level | P8: Yes | Q8: Yes | R8: 46311 | S8: 46289 | T8: Interested | U8: =IF(A8="","",IF(AND(R8<>"",R8<=TODAY()+30,P8="Yes",Q8="Yes",N8<>"Do Not Contact"),1,0)) -> 1 | V8: =IF(U8=1,COUNTIF($U$2:U8,1),"") -> 1 | W8: =IF(A8="","",A8&" | "&C8) -> CAN-2026-00007 | Nicole Brown | X8: =IF(A8="","",IF(AND(R8<>"",P8="Yes",Q8="Yes",N8<>"Do Not Contact"),IF(INT(R8)=TODAY(),1,IF(INT(R8)=TODAY()+1,2,0)),0)) -> 0 | Y8: =IF(OR(X8=1,X8=2),COUNTIF($X$2:X8,1)+COUNTIF($X$2:X8,2),"")
A9: CAN-2026-00008 | B9: 46121 | C9: Jessica Miller | D9: jessica.miller@example.com | E9: Quality Engineer | F9: Engineering | G9: ISO 9001, SPC, Internal Audit, Root Cause Analysis, FMEA, Email Marketing, B2B Sales | H9: 10 | I9: 86000 | J9: Atlanta, GA | K9: 60 | L9: Indeed | M9: Screened | N9: Potential Future Fit | O9: Passed CV screening | P9: Yes | Q9: Yes | R9: =TODAY() -> 46300 | U9: =IF(A9="","",IF(AND(R9<>"",R9<=TODAY()+30,P9="Yes",Q9="Yes",N9<>"Do Not Contact"),1,0)) -> 1 | V9: =IF(U9=1,COUNTIF($U$2:U9,1),"") -> 2 | W9: =IF(A9="","",A9&" | "&C9) -> CAN-2026-00008 | Jessica Miller | X9: =IF(A9="","",IF(AND(R9<>"",P9="Yes",Q9="Yes",N9<>"Do Not Contact"),IF(INT(R9)=TODAY(),1,IF(INT(R9)=TODAY()+1,2,0)),0)) -> 1 | Y9: =IF(OR(X9=1,X9=2),COUNTIF($X$2:X9,1)+COUNTIF($X$2:X9,2),"") -> 1
A10: CAN-2026-00009 | B10: 46128 | C10: Ashley Williams | D10: ashley.williams@example.com | E10: Marketing Manager | F10: Marketing | G10: Budgeting, Email Marketing, Google Analytics, SEO, CRM, Onboarding | H10: 10 | I10: 79000 | J10: Austin, TX | K10: 14 | L10: Indeed | M10: Withdrawn | N10: Not Currently Relevant | O10: Relocation not possible | P10: Yes | Q10: Yes | U10: =IF(A10="","",IF(AND(R10<>"",R10<=TODAY()+30,P10="Yes",Q10="Yes",N10<>"Do Not Contact"),1,0)) -> 0 | V10: =IF(U10=1,COUNTIF($U$2:U10,1),"") | W10: =IF(A10="","",A10&" | "&C10) -> CAN-2026-00009 | Ashley Williams | X10: =IF(A10="","",IF(AND(R10<>"",P10="Yes",Q10="Yes",N10<>"Do Not Contact"),IF(INT(R10)=TODAY(),1,IF(INT(R10)=TODAY()+1,2,0)),0)) -> 0 | Y10: =IF(OR(X10=1,X10=2),COUNTIF($X$2:X10,1)+COUNTIF($X$2:X10,2),"")
A11: CAN-2026-00010 | B11: 46132 | C11: Ashley Thompson | D11: ashley.thompson@example.com | E11: Marketing Manager | F11: Marketing | G11: Google Analytics, SEO, Content Strategy, Email Marketing, Root Cause Analysis | H11: 1 | I11: 114000 | J11: Atlanta, GA | K11: 30 | L11: Referral | M11: Screened | N11: Strong Future Fit | O11: Passed CV screening | P11: Yes | Q11: Yes | R11: 46371 | S11: 46285 | T11: Interested | U11: =IF(A11="","",IF(AND(R11<>"",R11<=TODAY()+30,P11="Yes",Q11="Yes",N11<>"Do Not Contact"),1,0)) -> 0 | V11: =IF(U11=1,COUNTIF($U$2:U11,1),"") | W11: =IF(A11="","",A11&" | "&C11) -> CAN-2026-00010 | Ashley Thompson | X11: =IF(A11="","",IF(AND(R11<>"",P11="Yes",Q11="Yes",N11<>"Do Not Contact"),IF(INT(R11)=TODAY(),1,IF(INT(R11)=TODAY()+1,2,0)),0)) -> 0 | Y11: =IF(OR(X11=1,X11=2),COUNTIF($X$2:X11,1)+COUNTIF($X$2:X11,2),"")
A12: CAN-2026-00011 | B12: 46137 | C12: Nicole Garcia | D12: nicole.garcia@example.com | E12: Account Executive | F12: Sales | G12: B2B Sales, Negotiation, Salesforce, CRM, Pipeline Management | H12: 5 | I12: 81000 | J12: Austin, TX | K12: 45 | L12: Company Website | M12: Interviewed | N12: Potential Future Fit | O12: Awaiting final decision | P12: Yes | Q12: Yes | R12: 46378 | U12: =IF(A12="","",IF(AND(R12<>"",R12<=TODAY()+30,P12="Yes",Q12="Yes",N12<>"Do Not Contact"),1,0)) -> 0 | V12: =IF(U12=1,COUNTIF($U$2:U12,1),"") | W12: =IF(A12="","",A12&" | "&C12) -> CAN-2026-00011 | Nicole Garcia | X12: =IF(A12="","",IF(AND(R12<>"",P12="Yes",Q12="Yes",N12<>"Do Not Contact"),IF(INT(R12)=TODAY(),1,IF(INT(R12)=TODAY()+1,2,0)),0)) -> 0 | Y12: =IF(OR(X12=1,X12=2),COUNTIF($X$2:X12,1)+COUNTIF($X$2:X12,2),"")
A13: CAN-2026-00012 | B13: 46137 | C13: Brittany Thomas | D13: brittany.thomas@example.com | E13: Account Executive | F13: Sales | G13: Pipeline Management, CRM, Salesforce, B2B Sales, Negotiation, FMEA | H13: 8 | I13: 87000 | J13: Dallas, TX | K13: 30 | L13: Company Website | M13: Interviewed | N13: Potential Future Fit | O13: Awaiting final decision | P13: Yes | Q13: Yes | R13: 46366 | U13: =IF(A13="","",IF(AND(R13<>"",R13<=TODAY()+30,P13="Yes",Q13="Yes",N13<>"Do Not Contact"),1,0)) -> 0 | V13: =IF(U13=1,COUNTIF($U$2:U13,1),"") | W13: =IF(A13="","",A13&" | "&C13) -> CAN-2026-00012 | Brittany Thomas | X13: =IF(A13="","",IF(AND(R13<>"",P13="Yes",Q13="Yes",N13<>"Do Not Contact"),IF(INT(R13)=TODAY(),1,IF(INT(R13)=TODAY()+1,2,0)),0)) -> 0 | Y13: =IF(OR(X13=1,X13=2),COUNTIF($X$2:X13,1)+COUNTIF($X$2:X13,2),"")
A14: CAN-2026-00013 | B14: 46139 | C14: Jessica Thomas | D14: jessica.thomas@example.com | E14: Marketing Manager | F14: Marketing | G14: Google Analytics, Content Strategy, Budgeting, Root Cause Analysis, Onboarding | H14: 10 | I14: 110000 | J14: Austin, TX | K14: 14 | L14: Company Website | M14: Not Selected | N14: Potential Future Fit | O14: Salary expectation above budget | P14: Yes | Q14: Yes | R14: =TODAY() -> 46300 | U14: =IF(A14="","",IF(AND(R14<>"",R14<=TODAY()+30,P14="Yes",Q14="Yes",N14<>"Do Not Contact"),1,0)) -> 1 | V14: =IF(U14=1,COUNTIF($U$2:U14,1),"") -> 3 | W14: =IF(A14="","",A14&" | "&C14) -> CAN-2026-00013 | Jessica Thomas | X14: =IF(A14="","",IF(AND(R14<>"",P14="Yes",Q14="Yes",N14<>"Do Not Contact"),IF(INT(R14)=TODAY(),1,IF(INT(R14)=TODAY()+1,2,0)),0)) -> 1 | Y14: =IF(OR(X14=1,X14=2),COUNTIF($X$2:X14,1)+COUNTIF($X$2:X14,2),"") -> 2
A15: CAN-2026-00014 | B15: 46143 | C15: Christopher Garcia | D15: christopher.garcia@example.com | E15: Operations Manager | F15: Operations | G15: Supply Chain, Team Leadership, Lean Six Sigma, Process Improvement | H15: 2 | I15: 125000 | J15: Atlanta, GA | K15: 0 | L15: Indeed | M15: Not Selected | N15: Do Not Contact | O15: Salary expectation above budget | P15: No | Q15: Yes | U15: =IF(A15="","",IF(AND(R15<>"",R15<=TODAY()+30,P15="Yes",Q15="Yes",N15<>"Do Not Contact"),1,0)) -> 0 | V15: =IF(U15=1,COUNTIF($U$2:U15,1),"") | W15: =IF(A15="","",A15&" | "&C15) -> CAN-2026-00014 | Christopher Garcia | X15: =IF(A15="","",IF(AND(R15<>"",P15="Yes",Q15="Yes",N15<>"Do Not Contact"),IF(INT(R15)=TODAY(),1,IF(INT(R15)=TODAY()+1,2,0)),0)) -> 0 | Y15: =IF(OR(X15=1,X15=2),COUNTIF($X$2:X15,1)+COUNTIF($X$2:X15,2),"")
A16: CAN-2026-00015 | B16: 46146 | C16: Jason Miller | D16: jason.miller@example.com | E16: Operations Manager | F16: Operations | G16: Process Improvement, Lean Six Sigma, Team Leadership | H16: 4 | I16: 96000 | J16: Austin, TX | K16: 30 | L16: Referral | M16: Hired | N16: Not Currently Relevant | O16: Best overall fit | P16: Yes | Q16: Yes | U16: =IF(A16="","",IF(AND(R16<>"",R16<=TODAY()+30,P16="Yes",Q16="Yes",N16<>"Do Not Contact"),1,0)) -> 0 | V16: =IF(U16=1,COUNTIF($U$2:U16,1),"") | W16: =IF(A16="","",A16&" | "&C16) -> CAN-2026-00015 | Jason Miller | X16: =IF(A16="","",IF(AND(R16<>"",P16="Yes",Q16="Yes",N16<>"Do Not Contact"),IF(INT(R16)=TODAY(),1,IF(INT(R16)=TODAY()+1,2,0)),0)) -> 0 | Y16: =IF(OR(X16=1,X16=2),COUNTIF($X$2:X16,1)+COUNTIF($X$2:X16,2),"")
A17: CAN-2026-00016 | B17: 46151 | C17: Brittany Jackson | D17: brittany.jackson@example.com | E17: Data Analyst | F17: Analytics | G17: Excel, SQL, Python, Employee Relations | H17: 3 | I17: 96000 | J17: Denver, CO | K17: 30 | L17: Company Website | M17: Withdrawn | N17: Strong Future Fit | O17: Accepted another offer | P17: No | Q17: Yes | U17: =IF(A17="","",IF(AND(R17<>"",R17<=TODAY()+30,P17="Yes",Q17="Yes",N17<>"Do Not Contact"),1,0)) -> 0 | V17: =IF(U17=1,COUNTIF($U$2:U17,1),"") | W17: =IF(A17="","",A17&" | "&C17) -> CAN-2026-00016 | Brittany Jackson | X17: =IF(A17="","",IF(AND(R17<>"",P17="Yes",Q17="Yes",N17<>"Do Not Contact"),IF(INT(R17)=TODAY(),1,IF(INT(R17)=TODAY()+1,2,0)),0)) -> 0 | Y17: =IF(OR(X17=1,X17=2),COUNTIF($X$2:X17,1)+COUNTIF($X$2:X17,2),"")
A18: CAN-2026-00017 | B18: 46155 | C18: Emily Martin | D18: emily.martin@example.com | E18: Staff Accountant | F18: Finance | G18: GAAP, Reconciliation, Accounts Payable, QuickBooks, Excel, SEO, CRM | H18: 8 | I18: 56000 | J18: Dallas, TX | K18: 14 | L18: Indeed | M18: Not Selected | N18: Do Not Contact | O18: Insufficient experience for this level | P18: No | Q18: Yes | U18: =IF(A18="","",IF(AND(R18<>"",R18<=TODAY()+30,P18="Yes",Q18="Yes",N18<>"Do Not Contact"),1,0)) -> 0 | V18: =IF(U18=1,COUNTIF($U$2:U18,1),"") | W18: =IF(A18="","",A18&" | "&C18) -> CAN-2026-00017 | Emily Martin | X18: =IF(A18="","",IF(AND(R18<>"",P18="Yes",Q18="Yes",N18<>"Do Not Contact"),IF(INT(R18)=TODAY(),1,IF(INT(R18)=TODAY()+1,2,0)),0)) -> 0 | Y18: =IF(OR(X18=1,X18=2),COUNTIF($X$2:X18,1)+COUNTIF($X$2:X18,2),"")
A19: CAN-2026-00018 | B19: 46175 | C19: Jessica Anderson | D19: jessica.anderson@example.com | E19: Quality Engineer | F19: Engineering | G19: Root Cause Analysis, FMEA, ISO 9001 | H19: 3 | I19: 81000 | J19: Austin, TX | K19: 60 | L19: Indeed | M19: Not Selected | N19: Potential Future Fit | O19: Stronger candidate selected | P19: Yes | Q19: Yes | R19: =TODAY()+1 -> 46301 | U19: =IF(A19="","",IF(AND(R19<>"",R19<=TODAY()+30,P19="Yes",Q19="Yes",N19<>"Do Not Contact"),1,0)) -> 1 | V19: =IF(U19=1,COUNTIF($U$2:U19,1),"") -> 4 | W19: =IF(A19="","",A19&" | "&C19) -> CAN-2026-00018 | Jessica Anderson | X19: =IF(A19="","",IF(AND(R19<>"",P19="Yes",Q19="Yes",N19<>"Do Not Contact"),IF(INT(R19)=TODAY(),1,IF(INT(R19)=TODAY()+1,2,0)),0)) -> 2 | Y19: =IF(OR(X19=1,X19=2),COUNTIF($X$2:X19,1)+COUNTIF($X$2:X19,2),"") -> 3
A20: CAN-2026-00019 | B20: 46179 | C20: Jessica Wilson | D20: jessica.wilson@example.com | E20: Software Engineer | F20: Engineering | G20: AWS, SQL, Python, JavaScript, Excel, Recruiting | H20: 4 | I20: 112000 | J20: Austin, TX | K20: 14 | L20: Indeed | M20: Not Selected | N20: Not Currently Relevant | O20: Salary expectation above budget | P20: Yes | Q20: Yes | U20: =IF(A20="","",IF(AND(R20<>"",R20<=TODAY()+30,P20="Yes",Q20="Yes",N20<>"Do Not Contact"),1,0)) -> 0 | V20: =IF(U20=1,COUNTIF($U$2:U20,1),"") | W20: =IF(A20="","",A20&" | "&C20) -> CAN-2026-00019 | Jessica Wilson | X20: =IF(A20="","",IF(AND(R20<>"",P20="Yes",Q20="Yes",N20<>"Do Not Contact"),IF(INT(R20)=TODAY(),1,IF(INT(R20)=TODAY()+1,2,0)),0)) -> 0 | Y20: =IF(OR(X20=1,X20=2),COUNTIF($X$2:X20,1)+COUNTIF($X$2:X20,2),"")
A21: CAN-2026-00020 | B21: 46182 | C21: Ashley Thomas | D21: ashley.thomas@example.com | E21: Marketing Manager | F21: Marketing | G21: Budgeting, Google Analytics, SEO, ISO 9001, FMEA | H21: 3 | I21: 79000 | J21: Columbus, OH | K21: 60 | L21: Company Website | M21: Withdrawn | N21: Potential Future Fit | O21: Relocation not possible | P21: Yes | Q21: Yes | R21: 46283 | U21: =IF(A21="","",IF(AND(R21<>"",R21<=TODAY()+30,P21="Yes",Q21="Yes",N21<>"Do Not Contact"),1,0)) -> 1 | V21: =IF(U21=1,COUNTIF($U$2:U21,1),"") -> 5 | W21: =IF(A21="","",A21&" | "&C21) -> CAN-2026-00020 | Ashley Thomas | X21: =IF(A21="","",IF(AND(R21<>"",P21="Yes",Q21="Yes",N21<>"Do Not Contact"),IF(INT(R21)=TODAY(),1,IF(INT(R21)=TODAY()+1,2,0)),0)) -> 0 | Y21: =IF(OR(X21=1,X21=2),COUNTIF($X$2:X21,1)+COUNTIF($X$2:X21,2),"")
A22: CAN-2026-00021 | B22: 46182 | C22: Tyler Jackson | D22: tyler.jackson@example.com | E22: Operations Manager | F22: Operations | G22: Process Improvement, Team Leadership, Budgeting, Tableau | H22: 9 | I22: 120000 | J22: Columbus, OH | K22: 14 | L22: LinkedIn | M22: Not Selected | N22: Strong Future Fit | O22: Salary expectation above budget | P22: Yes | Q22: No | R22: 46385 | U22: =IF(A22="","",IF(AND(R22<>"",R22<=TODAY()+30,P22="Yes",Q22="Yes",N22<>"Do Not Contact"),1,0)) -> 0 | V22: =IF(U22=1,COUNTIF($U$2:U22,1),"") | W22: =IF(A22="","",A22&" | "&C22) -> CAN-2026-00021 | Tyler Jackson | X22: =IF(A22="","",IF(AND(R22<>"",P22="Yes",Q22="Yes",N22<>"Do Not Contact"),IF(INT(R22)=TODAY(),1,IF(INT(R22)=TODAY()+1,2,0)),0)) -> 0 | Y22: =IF(OR(X22=1,X22=2),COUNTIF($X$2:X22,1)+COUNTIF($X$2:X22,2),"")
A23: CAN-2026-00022 | B23: 46194 | C23: Megan Martin | D23: megan.martin@example.com | E23: Quality Engineer | F23: Engineering | G23: ISO 9001, SPC, FMEA, Root Cause Analysis | H23: 3 | I23: 76000 | J23: Dallas, TX | K23: 0 | L23: LinkedIn | M23: Not Selected | N23: Potential Future Fit | O23: Stronger candidate selected | P23: Yes | Q23: Yes | R23: =TODAY()+1 -> 46301 | U23: =IF(A23="","",IF(AND(R23<>"",R23<=TODAY()+30,P23="Yes",Q23="Yes",N23<>"Do Not Contact"),1,0)) -> 1 | V23: =IF(U23=1,COUNTIF($U$2:U23,1),"") -> 6 | W23: =IF(A23="","",A23&" | "&C23) -> CAN-2026-00022 | Megan Martin | X23: =IF(A23="","",IF(AND(R23<>"",P23="Yes",Q23="Yes",N23<>"Do Not Contact"),IF(INT(R23)=TODAY(),1,IF(INT(R23)=TODAY()+1,2,0)),0)) -> 2 | Y23: =IF(OR(X23=1,X23=2),COUNTIF($X$2:X23,1)+COUNTIF($X$2:X23,2),"") -> 4
A24: CAN-2026-00023 | B24: 46196 | C24: Sarah Martinez | D24: sarah.martinez@example.com | E24: Marketing Manager | F24: Marketing | G24: SEO, Budgeting, Content Strategy, Google Analytics, Email Marketing | H24: 6 | I24: 116000 | J24: Atlanta, GA | K24: 14 | L24: Indeed | M24: Not Selected | N24: Not Currently Relevant | O24: Stronger candidate selected | P24: Yes | Q24: Yes | U24: =IF(A24="","",IF(AND(R24<>"",R24<=TODAY()+30,P24="Yes",Q24="Yes",N24<>"Do Not Contact"),1,0)) -> 0 | V24: =IF(U24=1,COUNTIF($U$2:U24,1),"") | W24: =IF(A24="","",A24&" | "&C24) -> CAN-2026-00023 | Sarah Martinez | X24: =IF(A24="","",IF(AND(R24<>"",P24="Yes",Q24="Yes",N24<>"Do Not Contact"),IF(INT(R24)=TODAY(),1,IF(INT(R24)=TODAY()+1,2,0)),0)) -> 0 | Y24: =IF(OR(X24=1,X24=2),COUNTIF($X$2:X24,1)+COUNTIF($X$2:X24,2),"")
A25: CAN-2026-00024 | B25: 46197 | C25: Lauren Davis | D25: lauren.davis@example.com | E25: Staff Accountant | F25: Finance | G25: GAAP, Excel, Reconciliation, QuickBooks, Benefits Administration | H25: 5 | I25: 65000 | J25: Austin, TX | K25: 14 | L25: Staffing Agency | M25: Not Selected | N25: Not Currently Relevant | O25: Stronger candidate selected | P25: Yes | Q25: Yes | U25: =IF(A25="","",IF(AND(R25<>"",R25<=TODAY()+30,P25="Yes",Q25="Yes",N25<>"Do Not Contact"),1,0)) -> 0 | V25: =IF(U25=1,COUNTIF($U$2:U25,1),"") | W25: =IF(A25="","",A25&" | "&C25) -> CAN-2026-00024 | Lauren Davis | X25: =IF(A25="","",IF(AND(R25<>"",P25="Yes",Q25="Yes",N25<>"Do Not Contact"),IF(INT(R25)=TODAY(),1,IF(INT(R25)=TODAY()+1,2,0)),0)) -> 0 | Y25: =IF(OR(X25=1,X25=2),COUNTIF($X$2:X25,1)+COUNTIF($X$2:X25,2),"")
A26: CAN-2026-00025 | B26: 46199 | C26: Amanda Thompson | D26: amanda.thompson@example.com | E26: HR Generalist | F26: Human Resources | G26: Recruiting, Onboarding, HRIS, GAAP, Python | H26: 3 | I26: 65000 | J26: Chicago, IL | K26: 30 | L26: Referral | M26: Not Selected | N26: Potential Future Fit | O26: Skill gap in a key requirement | P26: Yes | Q26: Yes | R26: 46303 | U26: =IF(A26="","",IF(AND(R26<>"",R26<=TODAY()+30,P26="Yes",Q26="Yes",N26<>"Do Not Contact"),1,0)) -> 1 | V26: =IF(U26=1,COUNTIF($U$2:U26,1),"") -> 7 | W26: =IF(A26="","",A26&" | "&C26) -> CAN-2026-00025 | Amanda Thompson | X26: =IF(A26="","",IF(AND(R26<>"",P26="Yes",Q26="Yes",N26<>"Do Not Contact"),IF(INT(R26)=TODAY(),1,IF(INT(R26)=TODAY()+1,2,0)),0)) -> 0 | Y26: =IF(OR(X26=1,X26=2),COUNTIF($X$2:X26,1)+COUNTIF($X$2:X26,2),"")
A27: CAN-2026-00026 | B27: 46203 | C27: Jason White | D27: jason.white@example.com | E27: Staff Accountant | F27: Finance | G27: Accounts Payable, QuickBooks, Excel | H27: 5 | I27: 68000 | J27: Austin, TX | K27: 14 | L27: Staffing Agency | M27: Not Selected | N27: Potential Future Fit | O27: Stronger candidate selected | P27: Yes | Q27: Yes | R27: =TODAY()+1 -> 46301 | U27: =IF(A27="","",IF(AND(R27<>"",R27<=TODAY()+30,P27="Yes",Q27="Yes",N27<>"Do Not Contact"),1,0)) -> 1 | V27: =IF(U27=1,COUNTIF($U$2:U27,1),"") -> 8 | W27: =IF(A27="","",A27&" | "&C27) -> CAN-2026-00026 | Jason White | X27: =IF(A27="","",IF(AND(R27<>"",P27="Yes",Q27="Yes",N27<>"Do Not Contact"),IF(INT(R27)=TODAY(),1,IF(INT(R27)=TODAY()+1,2,0)),0)) -> 2 | Y27: =IF(OR(X27=1,X27=2),COUNTIF($X$2:X27,1)+COUNTIF($X$2:X27,2),"") -> 5
A28: CAN-2026-00027 | B28: 46210 | C28: Amanda Thomas | D28: amanda.thomas@example.com | E28: Quality Engineer | F28: Engineering | G28: Root Cause Analysis, FMEA, Internal Audit, SPC, ISO 9001 | H28: 8 | I28: 92000 | J28: Columbus, OH | K28: 30 | L28: Company Website | M28: Interviewed | N28: Not Currently Relevant | O28: Awaiting final decision | P28: Yes | Q28: No | U28: =IF(A28="","",IF(AND(R28<>"",R28<=TODAY()+30,P28="Yes",Q28="Yes",N28<>"Do Not Contact"),1,0)) -> 0 | V28: =IF(U28=1,COUNTIF($U$2:U28,1),"") | W28: =IF(A28="","",A28&" | "&C28) -> CAN-2026-00027 | Amanda Thomas | X28: =IF(A28="","",IF(AND(R28<>"",P28="Yes",Q28="Yes",N28<>"Do Not Contact"),IF(INT(R28)=TODAY(),1,IF(INT(R28)=TODAY()+1,2,0)),0)) -> 0 | Y28: =IF(OR(X28=1,X28=2),COUNTIF($X$2:X28,1)+COUNTIF($X$2:X28,2),"")
A29: CAN-2026-00028 | B29: 46217 | C29: Daniel Brown | D29: daniel.brown@example.com | E29: HR Generalist | F29: Human Resources | G29: HRIS, Benefits Administration, Employee Relations, Content Strategy, Negotiation | H29: 6 | I29: 62000 | J29: Dallas, TX | K29: 0 | L29: Staffing Agency | M29: Withdrawn | N29: Not Currently Relevant | O29: Relocation not possible | P29: No | Q29: Yes | U29: =IF(A29="","",IF(AND(R29<>"",R29<=TODAY()+30,P29="Yes",Q29="Yes",N29<>"Do Not Contact"),1,0)) -> 0 | V29: =IF(U29=1,COUNTIF($U$2:U29,1),"") | W29: =IF(A29="","",A29&" | "&C29) -> CAN-2026-00028 | Daniel Brown | X29: =IF(A29="","",IF(AND(R29<>"",P29="Yes",Q29="Yes",N29<>"Do Not Contact"),IF(INT(R29)=TODAY(),1,IF(INT(R29)=TODAY()+1,2,0)),0)) -> 0 | Y29: =IF(OR(X29=1,X29=2),COUNTIF($X$2:X29,1)+COUNTIF($X$2:X29,2),"")
A30: CAN-2026-00029 | B30: 46219 | C30: Megan Garcia | D30: megan.garcia@example.com | E30: Operations Manager | F30: Operations | G30: Process Improvement, Lean Six Sigma, Team Leadership, Budgeting, Supply Chain, Root Cause Analysis | H30: 2 | I30: 112000 | J30: Chicago, IL | K30: 60 | L30: Referral | M30: Hired | N30: Not Currently Relevant | O30: Best overall fit | P30: No | Q30: Yes | U30: =IF(A30="","",IF(AND(R30<>"",R30<=TODAY()+30,P30="Yes",Q30="Yes",N30<>"Do Not Contact"),1,0)) -> 0 | V30: =IF(U30=1,COUNTIF($U$2:U30,1),"") | W30: =IF(A30="","",A30&" | "&C30) -> CAN-2026-00029 | Megan Garcia | X30: =IF(A30="","",IF(AND(R30<>"",P30="Yes",Q30="Yes",N30<>"Do Not Contact"),IF(INT(R30)=TODAY(),1,IF(INT(R30)=TODAY()+1,2,0)),0)) -> 0 | Y30: =IF(OR(X30=1,X30=2),COUNTIF($X$2:X30,1)+COUNTIF($X$2:X30,2),"")
A31: CAN-2026-00030 | B31: 46219 | C31: Christopher Davis | D31: christopher.davis@example.com | E31: Data Analyst | F31: Analytics | G31: Reporting, Excel, Python, Tableau | H31: 5 | I31: 102000 | J31: Atlanta, GA | K31: 30 | L31: Indeed | M31: Not Selected | N31: Not Currently Relevant | O31: Insufficient experience for this level | P31: Yes | Q31: No | U31: =IF(A31="","",IF(AND(R31<>"",R31<=TODAY()+30,P31="Yes",Q31="Yes",N31<>"Do Not Contact"),1,0)) -> 0 | V31: =IF(U31=1,COUNTIF($U$2:U31,1),"") | W31: =IF(A31="","",A31&" | "&C31) -> CAN-2026-00030 | Christopher Davis | X31: =IF(A31="","",IF(AND(R31<>"",P31="Yes",Q31="Yes",N31<>"Do Not Contact"),IF(INT(R31)=TODAY(),1,IF(INT(R31)=TODAY()+1,2,0)),0)) -> 0 | Y31: =IF(OR(X31=1,X31=2),COUNTIF($X$2:X31,1)+COUNTIF($X$2:X31,2),"")
A32: CAN-2026-00031 | B32: 46225 | C32: Kevin Taylor | D32: kevin.taylor@example.com | E32: Account Executive | F32: Sales | G32: Pipeline Management, B2B Sales, Negotiation, Salesforce, Lean Six Sigma, Supply Chain | H32: 8 | I32: 81000 | J32: Chicago, IL | K32: 45 | L32: Company Website | M32: Screened | N32: Strong Future Fit | O32: Passed CV screening | P32: Yes | Q32: Yes | R32: =TODAY()-2 -> 46298 | U32: =IF(A32="","",IF(AND(R32<>"",R32<=TODAY()+30,P32="Yes",Q32="Yes",N32<>"Do Not Contact"),1,0)) -> 1 | V32: =IF(U32=1,COUNTIF($U$2:U32,1),"") -> 9 | W32: =IF(A32="","",A32&" | "&C32) -> CAN-2026-00031 | Kevin Taylor | X32: =IF(A32="","",IF(AND(R32<>"",P32="Yes",Q32="Yes",N32<>"Do Not Contact"),IF(INT(R32)=TODAY(),1,IF(INT(R32)=TODAY()+1,2,0)),0)) -> 0 | Y32: =IF(OR(X32=1,X32=2),COUNTIF($X$2:X32,1)+COUNTIF($X$2:X32,2),"")
A33: CAN-2026-00032 | B33: 46227 | C33: Ashley Taylor | D33: ashley.taylor@example.com | E33: Staff Accountant | F33: Finance | G33: QuickBooks, Accounts Payable, Excel | H33: 4 | I33: 79000 | J33: Denver, CO | K33: 45 | L33: Company Website | M33: Hired | N33: Not Currently Relevant | O33: Best overall fit | P33: Yes | Q33: Yes | U33: =IF(A33="","",IF(AND(R33<>"",R33<=TODAY()+30,P33="Yes",Q33="Yes",N33<>"Do Not Contact"),1,0)) -> 0 | V33: =IF(U33=1,COUNTIF($U$2:U33,1),"") | W33: =IF(A33="","",A33&" | "&C33) -> CAN-2026-00032 | Ashley Taylor | X33: =IF(A33="","",IF(AND(R33<>"",P33="Yes",Q33="Yes",N33<>"Do Not Contact"),IF(INT(R33)=TODAY(),1,IF(INT(R33)=TODAY()+1,2,0)),0)) -> 0 | Y33: =IF(OR(X33=1,X33=2),COUNTIF($X$2:X33,1)+COUNTIF($X$2:X33,2),"")
A34: CAN-2026-00033 | B34: 46233 | C34: Tyler White | D34: tyler.white@example.com | E34: Data Analyst | F34: Analytics | G34: Python, Reporting, Excel, SQL, Tableau | H34: 8 | I34: 95000 | J34: Austin, TX | K34: 60 | L34: Referral | M34: Screened | N34: Not Currently Relevant | O34: Passed CV screening | P34: Yes | Q34: No | U34: =IF(A34="","",IF(AND(R34<>"",R34<=TODAY()+30,P34="Yes",Q34="Yes",N34<>"Do Not Contact"),1,0)) -> 0 | V34: =IF(U34=1,COUNTIF($U$2:U34,1),"") | W34: =IF(A34="","",A34&" | "&C34) -> CAN-2026-00033 | Tyler White | X34: =IF(A34="","",IF(AND(R34<>"",P34="Yes",Q34="Yes",N34<>"Do Not Contact"),IF(INT(R34)=TODAY(),1,IF(INT(R34)=TODAY()+1,2,0)),0)) -> 0 | Y34: =IF(OR(X34=1,X34=2),COUNTIF($X$2:X34,1)+COUNTIF($X$2:X34,2),"")
A35: CAN-2026-00034 | B35: 46236 | C35: Nicole Miller | D35: nicole.miller@example.com | E35: Data Analyst | F35: Analytics | G35: Reporting, SQL, Python, Tableau, Google Analytics, Budgeting | H35: 8 | I35: 72000 | J35: Columbus, OH | K35: 60 | L35: Company Website | M35: Not Selected | N35: Strong Future Fit | O35: Insufficient experience for this level | P35: Yes | Q35: Yes | R35: 46326 | U35: =IF(A35="","",IF(AND(R35<>"",R35<=TODAY()+30,P35="Yes",Q35="Yes",N35<>"Do Not Contact"),1,0)) -> 1 | V35: =IF(U35=1,COUNTIF($U$2:U35,1),"") -> 10 | W35: =IF(A35="","",A35&" | "&C35) -> CAN-2026-00034 | Nicole Miller | X35: =IF(A35="","",IF(AND(R35<>"",P35="Yes",Q35="Yes",N35<>"Do Not Contact"),IF(INT(R35)=TODAY(),1,IF(INT(R35)=TODAY()+1,2,0)),0)) -> 0 | Y35: =IF(OR(X35=1,X35=2),COUNTIF($X$2:X35,1)+COUNTIF($X$2:X35,2),"")
A36: CAN-2026-00035 | B36: 46243 | C36: Rachel Taylor | D36: rachel.taylor@example.com | E36: Quality Engineer | F36: Engineering | G36: FMEA, ISO 9001, Root Cause Analysis, Internal Audit, Team Leadership, Git | H36: 4 | I36: 75000 | J36: Austin, TX | K36: 45 | L36: Company Website | M36: Hired | N36: Not Currently Relevant | O36: Best overall fit | P36: No | Q36: Yes | U36: =IF(A36="","",IF(AND(R36<>"",R36<=TODAY()+30,P36="Yes",Q36="Yes",N36<>"Do Not Contact"),1,0)) -> 0 | V36: =IF(U36=1,COUNTIF($U$2:U36,1),"") | W36: =IF(A36="","",A36&" | "&C36) -> CAN-2026-00035 | Rachel Taylor | X36: =IF(A36="","",IF(AND(R36<>"",P36="Yes",Q36="Yes",N36<>"Do Not Contact"),IF(INT(R36)=TODAY(),1,IF(INT(R36)=TODAY()+1,2,0)),0)) -> 0 | Y36: =IF(OR(X36=1,X36=2),COUNTIF($X$2:X36,1)+COUNTIF($X$2:X36,2),"")
A37: CAN-2026-00036 | B37: 46244 | C37: Christopher Thompson | D37: christopher.thompson@example.com | E37: Software Engineer | F37: Engineering | G37: Git, SQL, AWS, Python, JavaScript, Email Marketing | H37: 7 | I37: 155000 | J37: Chicago, IL | K37: 14 | L37: LinkedIn | M37: Interviewed | N37: Potential Future Fit | O37: Awaiting final decision | P37: Yes | Q37: Yes | R37: 46297 | U37: =IF(A37="","",IF(AND(R37<>"",R37<=TODAY()+30,P37="Yes",Q37="Yes",N37<>"Do Not Contact"),1,0)) -> 1 | V37: =IF(U37=1,COUNTIF($U$2:U37,1),"") -> 11 | W37: =IF(A37="","",A37&" | "&C37) -> CAN-2026-00036 | Christopher Thompson | X37: =IF(A37="","",IF(AND(R37<>"",P37="Yes",Q37="Yes",N37<>"Do Not Contact"),IF(INT(R37)=TODAY(),1,IF(INT(R37)=TODAY()+1,2,0)),0)) -> 0 | Y37: =IF(OR(X37=1,X37=2),COUNTIF($X$2:X37,1)+COUNTIF($X$2:X37,2),"")
A38: CAN-2026-00037 | B38: 46247 | C38: Ashley Miller | D38: ashley.miller@example.com | E38: Data Analyst | F38: Analytics | G38: Python, SQL, Tableau, Reporting, Excel | H38: 5 | I38: 101000 | J38: Denver, CO | K38: 30 | L38: Staffing Agency | M38: Not Selected | N38: Potential Future Fit | O38: Insufficient experience for this level | P38: Yes | Q38: Yes | R38: =TODAY()+7 -> 46307 | U38: =IF(A38="","",IF(AND(R38<>"",R38<=TODAY()+30,P38="Yes",Q38="Yes",N38<>"Do Not Contact"),1,0)) -> 1 | V38: =IF(U38=1,COUNTIF($U$2:U38,1),"") -> 12 | W38: =IF(A38="","",A38&" | "&C38) -> CAN-2026-00037 | Ashley Miller | X38: =IF(A38="","",IF(AND(R38<>"",P38="Yes",Q38="Yes",N38<>"Do Not Contact"),IF(INT(R38)=TODAY(),1,IF(INT(R38)=TODAY()+1,2,0)),0)) -> 0 | Y38: =IF(OR(X38=1,X38=2),COUNTIF($X$2:X38,1)+COUNTIF($X$2:X38,2),"")
A39: CAN-2026-00038 | B39: 46258 | C39: Emily Martinez | D39: emily.martinez@example.com | E39: HR Generalist | F39: Human Resources | G39: HRIS, Recruiting, Onboarding, Employee Relations, Google Analytics, Python | H39: 9 | I39: 85000 | J39: Denver, CO | K39: 0 | L39: Company Website | M39: Not Selected | N39: Not Currently Relevant | O39: Timing: could not start soon enough | P39: Yes | Q39: Yes | U39: =IF(A39="","",IF(AND(R39<>"",R39<=TODAY()+30,P39="Yes",Q39="Yes",N39<>"Do Not Contact"),1,0)) -> 0 | V39: =IF(U39=1,COUNTIF($U$2:U39,1),"") | W39: =IF(A39="","",A39&" | "&C39) -> CAN-2026-00038 | Emily Martinez | X39: =IF(A39="","",IF(AND(R39<>"",P39="Yes",Q39="Yes",N39<>"Do Not Contact"),IF(INT(R39)=TODAY(),1,IF(INT(R39)=TODAY()+1,2,0)),0)) -> 0 | Y39: =IF(OR(X39=1,X39=2),COUNTIF($X$2:X39,1)+COUNTIF($X$2:X39,2),"")
A40: CAN-2026-00039 | B40: 46259 | C40: Kevin Miller | D40: kevin.miller@example.com | E40: Operations Manager | F40: Operations | G40: Supply Chain, Team Leadership, Budgeting, Process Improvement, Lean Six Sigma, Onboarding, Root Cause Analysis | H40: 4 | I40: 88000 | J40: Chicago, IL | K40: 14 | L40: Referral | M40: Not Selected | N40: Potential Future Fit | O40: Stronger candidate selected | P40: Yes | Q40: Yes | R40: 46362 | U40: =IF(A40="","",IF(AND(R40<>"",R40<=TODAY()+30,P40="Yes",Q40="Yes",N40<>"Do Not Contact"),1,0)) -> 0 | V40: =IF(U40=1,COUNTIF($U$2:U40,1),"") | W40: =IF(A40="","",A40&" | "&C40) -> CAN-2026-00039 | Kevin Miller | X40: =IF(A40="","",IF(AND(R40<>"",P40="Yes",Q40="Yes",N40<>"Do Not Contact"),IF(INT(R40)=TODAY(),1,IF(INT(R40)=TODAY()+1,2,0)),0)) -> 0 | Y40: =IF(OR(X40=1,X40=2),COUNTIF($X$2:X40,1)+COUNTIF($X$2:X40,2),"")
...

Sheet Follow-Up
A1: Follow-Up
A2: 🔒 PREMIUM FEATURE · Visible in the demo, locked until you get full access. Message the creator (Start Here tab) to unlock it.
A4: 📝 A. Log a follow-up | E4: What each outcome does
A5: 1. Choose the candidate | C5: Pick from the list (ID | name) | E5: Interested: stays in the pool, next follow-up date is updated.
A6: Candidate (automatic) | B6: =IFERROR(INDEX(Candidates!$C$2:$C$201,MATCH(LEFT(B5,FIND(" | ",B5&" | ")-1),Candidates!$A$2:$A$201,0))&" - last applied: "&INDEX(Candidates!$E$2:$E$201,MATCH(LEFT(B5,FIND(" | ",B5&" | ")-1),Candidates!$A$2:$A$201,0)),"") | C6: Check that this is the right person | E6: No response: stays in the pool, set a new follow-up date.
A7: 2. Date you contacted them | C7: e.g. 10/05/2026 (MM/DD/YYYY) | E7: Hired elsewhere: follow-up is cleared unless you enter a new date.
A8: 3. Outcome | C8: What was the result? | E8: Not interested: marked 'Interested in future roles = No' and removed from follow-up.
A9: 4. Notes (optional) | C9: Short note | E9: Do not contact again: marked Do Not Contact and excluded from all matching.
A10: 5. Next follow-up date (optional) | C10: Leave empty if no more follow-up is needed
A11: Then click SAVE FOLLOW-UP (or menu Talent Pool > Save follow-up).
A13: ⏰ B. Due now (next 30 days, including overdue)
A14: ="Total due: "&COUNTIF(Candidates!$U$2:$U$201,1) -> Total due: 13
A15: Candidate ID | B15: Name | C15: Contact | D15: Last position applied | E15: Future potential | F15: Next follow-up | G15: Status | H15: Last contact | I15: Last outcome
A16: =IFERROR(INDEX(Candidates!$A$2:$A$201,MATCH(1,Candidates!$V$2:$V$201,0))&"","") -> CAN-2026-00007 | B16: =IFERROR(INDEX(Candidates!$C$2:$C$201,MATCH(1,Candidates!$V$2:$V$201,0))&"","") -> Nicole Brown | C16: =IFERROR(INDEX(Candidates!$D$2:$D$201,MATCH(1,Candidates!$V$2:$V$201,0))&"","") -> nicole.brown@example.com | D16: =IFERROR(INDEX(Candidates!$E$2:$E$201,MATCH(1,Candidates!$V$2:$V$201,0))&"","") -> Marketing Manager | E16: =IFERROR(INDEX(Candidates!$N$2:$N$201,MATCH(1,Candidates!$V$2:$V$201,0))&"","") -> Strong Future Fit | F16: =IFERROR(IF(INDEX(Candidates!$R$2:$R$201,MATCH(1,Candidates!$V$2:$V$201,0))="","",INDEX(Candidates!$R$2:$R$201,MATCH(1,Candidates!$V$2:$V$201,0))),"") -> 46311 | G16: =IF(F16="","",IF(F16<TODAY(),"Overdue by "&(TODAY()-F16)&" days",IF(F16=TODAY(),"Due today","Due in "&(F16-TODAY())&" days"))) -> Due in 11 days | H16: =IFERROR(IF(INDEX(Candidates!$S$2:$S$201,MATCH(1,Candidates!$V$2:$V$201,0))="","",INDEX(Candidates!$S$2:$S$201,MATCH(1,Candidates!$V$2:$V$201,0))),"") -> 46289 | I16: =IFERROR(INDEX(Candidates!$T$2:$T$201,MATCH(1,Candidates!$V$2:$V$201,0))&"","") -> Interested
A17: =IFERROR(INDEX(Candidates!$A$2:$A$201,MATCH(2,Candidates!$V$2:$V$201,0))&"","") -> CAN-2026-00008 | B17: =IFERROR(INDEX(Candidates!$C$2:$C$201,MATCH(2,Candidates!$V$2:$V$201,0))&"","") -> Jessica Miller | C17: =IFERROR(INDEX(Candidates!$D$2:$D$201,MATCH(2,Candidates!$V$2:$V$201,0))&"","") -> jessica.miller@example.com | D17: =IFERROR(INDEX(Candidates!$E$2:$E$201,MATCH(2,Candidates!$V$2:$V$201,0))&"","") -> Quality Engineer | E17: =IFERROR(INDEX(Candidates!$N$2:$N$201,MATCH(2,Candidates!$V$2:$V$201,0))&"","") -> Potential Future Fit | F17: =IFERROR(IF(INDEX(Candidates!$R$2:$R$201,MATCH(2,Candidates!$V$2:$V$201,0))="","",INDEX(Candidates!$R$2:$R$201,MATCH(2,Candidates!$V$2:$V$201,0))),"") -> 46300 | G17: =IF(F17="","",IF(F17<TODAY(),"Overdue by "&(TODAY()-F17)&" days",IF(F17=TODAY(),"Due today","Due in "&(F17-TODAY())&" days"))) -> Due today | H17: =IFERROR(IF(INDEX(Candidates!$S$2:$S$201,MATCH(2,Candidates!$V$2:$V$201,0))="","",INDEX(Candidates!$S$2:$S$201,MATCH(2,Candidates!$V$2:$V$201,0))),"") | I17: =IFERROR(INDEX(Candidates!$T$2:$T$201,MATCH(2,Candidates!$V$2:$V$201,0))&"","")
A18: =IFERROR(INDEX(Candidates!$A$2:$A$201,MATCH(3,Candidates!$V$2:$V$201,0))&"","") -> CAN-2026-00013 | B18: =IFERROR(INDEX(Candidates!$C$2:$C$201,MATCH(3,Candidates!$V$2:$V$201,0))&"","") -> Jessica Thomas | C18: =IFERROR(INDEX(Candidates!$D$2:$D$201,MATCH(3,Candidates!$V$2:$V$201,0))&"","") -> jessica.thomas@example.com | D18: =IFERROR(INDEX(Candidates!$E$2:$E$201,MATCH(3,Candidates!$V$2:$V$201,0))&"","") -> Marketing Manager | E18: =IFERROR(INDEX(Candidates!$N$2:$N$201,MATCH(3,Candidates!$V$2:$V$201,0))&"","") -> Potential Future Fit | F18: =IFERROR(IF(INDEX(Candidates!$R$2:$R$201,MATCH(3,Candidates!$V$2:$V$201,0))="","",INDEX(Candidates!$R$2:$R$201,MATCH(3,Candidates!$V$2:$V$201,0))),"") -> 46300 | G18: =IF(F18="","",IF(F18<TODAY(),"Overdue by "&(TODAY()-F18)&" days",IF(F18=TODAY(),"Due today","Due in "&(F18-TODAY())&" days"))) -> Due today | H18: =IFERROR(IF(INDEX(Candidates!$S$2:$S$201,MATCH(3,Candidates!$V$2:$V$201,0))="","",INDEX(Candidates!$S$2:$S$201,MATCH(3,Candidates!$V$2:$V$201,0))),"") | I18: =IFERROR(INDEX(Candidates!$T$2:$T$201,MATCH(3,Candidates!$V$2:$V$201,0))&"","")
A19: =IFERROR(INDEX(Candidates!$A$2:$A$201,MATCH(4,Candidates!$V$2:$V$201,0))&"","") -> CAN-2026-00018 | B19: =IFERROR(INDEX(Candidates!$C$2:$C$201,MATCH(4,Candidates!$V$2:$V$201,0))&"","") -> Jessica Anderson | C19: =IFERROR(INDEX(Candidates!$D$2:$D$201,MATCH(4,Candidates!$V$2:$V$201,0))&"","") -> jessica.anderson@example.com | D19: =IFERROR(INDEX(Candidates!$E$2:$E$201,MATCH(4,Candidates!$V$2:$V$201,0))&"","") -> Quality Engineer | E19: =IFERROR(INDEX(Candidates!$N$2:$N$201,MATCH(4,Candidates!$V$2:$V$201,0))&"","") -> Potential Future Fit | F19: =IFERROR(IF(INDEX(Candidates!$R$2:$R$201,MATCH(4,Candidates!$V$2:$V$201,0))="","",INDEX(Candidates!$R$2:$R$201,MATCH(4,Candidates!$V$2:$V$201,0))),"") -> 46301 | G19: =IF(F19="","",IF(F19<TODAY(),"Overdue by "&(TODAY()-F19)&" days",IF(F19=TODAY(),"Due today","Due in "&(F19-TODAY())&" days"))) -> Due in 1 days | H19: =IFERROR(IF(INDEX(Candidates!$S$2:$S$201,MATCH(4,Candidates!$V$2:$V$201,0))="","",INDEX(Candidates!$S$2:$S$201,MATCH(4,Candidates!$V$2:$V$201,0))),"") | I19: =IFERROR(INDEX(Candidates!$T$2:$T$201,MATCH(4,Candidates!$V$2:$V$201,0))&"","")
A20: =IFERROR(INDEX(Candidates!$A$2:$A$201,MATCH(5,Candidates!$V$2:$V$201,0))&"","") -> CAN-2026-00020 | B20: =IFERROR(INDEX(Candidates!$C$2:$C$201,MATCH(5,Candidates!$V$2:$V$201,0))&"","") -> Ashley Thomas | C20: =IFERROR(INDEX(Candidates!$D$2:$D$201,MATCH(5,Candidates!$V$2:$V$201,0))&"","") -> ashley.thomas@example.com | D20: =IFERROR(INDEX(Candidates!$E$2:$E$201,MATCH(5,Candidates!$V$2:$V$201,0))&"","") -> Marketing Manager | E20: =IFERROR(INDEX(Candidates!$N$2:$N$201,MATCH(5,Candidates!$V$2:$V$201,0))&"","") -> Potential Future Fit | F20: =IFERROR(IF(INDEX(Candidates!$R$2:$R$201,MATCH(5,Candidates!$V$2:$V$201,0))="","",INDEX(Candidates!$R$2:$R$201,MATCH(5,Candidates!$V$2:$V$201,0))),"") -> 46283 | G20: =IF(F20="","",IF(F20<TODAY(),"Overdue by "&(TODAY()-F20)&" days",IF(F20=TODAY(),"Due today","Due in "&(F20-TODAY())&" days"))) -> Overdue by 17 days | H20: =IFERROR(IF(INDEX(Candidates!$S$2:$S$201,MATCH(5,Candidates!$V$2:$V$201,0))="","",INDEX(Candidates!$S$2:$S$201,MATCH(5,Candidates!$V$2:$V$201,0))),"") | I20: =IFERROR(INDEX(Candidates!$T$2:$T$201,MATCH(5,Candidates!$V$2:$V$201,0))&"","")
A21: =IFERROR(INDEX(Candidates!$A$2:$A$201,MATCH(6,Candidates!$V$2:$V$201,0))&"","") -> CAN-2026-00022 | B21: =IFERROR(INDEX(Candidates!$C$2:$C$201,MATCH(6,Candidates!$V$2:$V$201,0))&"","") -> Megan Martin | C21: =IFERROR(INDEX(Candidates!$D$2:$D$201,MATCH(6,Candidates!$V$2:$V$201,0))&"","") -> megan.martin@example.com | D21: =IFERROR(INDEX(Candidates!$E$2:$E$201,MATCH(6,Candidates!$V$2:$V$201,0))&"","") -> Quality Engineer | E21: =IFERROR(INDEX(Candidates!$N$2:$N$201,MATCH(6,Candidates!$V$2:$V$201,0))&"","") -> Potential Future Fit | F21: =IFERROR(IF(INDEX(Candidates!$R$2:$R$201,MATCH(6,Candidates!$V$2:$V$201,0))="","",INDEX(Candidates!$R$2:$R$201,MATCH(6,Candidates!$V$2:$V$201,0))),"") -> 46301 | G21: =IF(F21="","",IF(F21<TODAY(),"Overdue by "&(TODAY()-F21)&" days",IF(F21=TODAY(),"Due today","Due in "&(F21-TODAY())&" days"))) -> Due in 1 days | H21: =IFERROR(IF(INDEX(Candidates!$S$2:$S$201,MATCH(6,Candidates!$V$2:$V$201,0))="","",INDEX(Candidates!$S$2:$S$201,MATCH(6,Candidates!$V$2:$V$201,0))),"") | I21: =IFERROR(INDEX(Candidates!$T$2:$T$201,MATCH(6,Candidates!$V$2:$V$201,0))&"","")
A22: =IFERROR(INDEX(Candidates!$A$2:$A$201,MATCH(7,Candidates!$V$2:$V$201,0))&"","") -> CAN-2026-00025 | B22: =IFERROR(INDEX(Candidates!$C$2:$C$201,MATCH(7,Candidates!$V$2:$V$201,0))&"","") -> Amanda Thompson | C22: =IFERROR(INDEX(Candidates!$D$2:$D$201,MATCH(7,Candidates!$V$2:$V$201,0))&"","") -> amanda.thompson@example.com | D22: =IFERROR(INDEX(Candidates!$E$2:$E$201,MATCH(7,Candidates!$V$2:$V$201,0))&"","") -> HR Generalist | E22: =IFERROR(INDEX(Candidates!$N$2:$N$201,MATCH(7,Candidates!$V$2:$V$201,0))&"","") -> Potential Future Fit | F22: =IFERROR(IF(INDEX(Candidates!$R$2:$R$201,MATCH(7,Candidates!$V$2:$V$201,0))="","",INDEX(Candidates!$R$2:$R$201,MATCH(7,Candidates!$V$2:$V$201,0))),"") -> 46303 | G22: =IF(F22="","",IF(F22<TODAY(),"Overdue by "&(TODAY()-F22)&" days",IF(F22=TODAY(),"Due today","Due in "&(F22-TODAY())&" days"))) -> Due in 3 days | H22: =IFERROR(IF(INDEX(Candidates!$S$2:$S$201,MATCH(7,Candidates!$V$2:$V$201,0))="","",INDEX(Candidates!$S$2:$S$201,MATCH(7,Candidates!$V$2:$V$201,0))),"") | I22: =IFERROR(INDEX(Candidates!$T$2:$T$201,MATCH(7,Candidates!$V$2:$V$201,0))&"","")
